<?xml version="1.0" ?>
<!-- Generated using onshape-to-robot -->
<robot name="hiro-urdf3">
  <!-- Link base_link -->
  <link name="base_link"/>
  <joint name="base_to_torso" type="fixed">
      <parent link="base_link"/>
      <child link="torso_kidsize25"/>
      <origin xyz="0 0 0.5"/>
  </joint>
  <!-- Link torso_kidsize25 -->
  <link name="torso_kidsize25">
    <inertial>
      <origin xyz="0.146105 0.00568445 0.349252" rpy="0 0 0"/>
      <mass value="2.16719"/>
      <inertia ixx="0.00929033" ixy="-9.38024e-07" ixz="8.09787e-07" iyy="0.00982507" iyz="0.000706149" izz="0.00934245"/>
    </inertial>
    <!-- Part mx_64t_mir1 -->
    <collision>
      <origin xyz="0.19561 0.0108657 0.296066" rpy="1.14304e-14 2.1517e-13 -6.55847e-15"/>
      <geometry>
        <mesh filename="package://assets/mx_64t_mir1.stl"/>
      </geometry>
    </collision>
    <!-- Part mx_64t -->
    <collision>
      <origin xyz="0.0966103 0.0108641 0.296066" rpy="3.14159 -2.15281e-13 3.14159"/>
      <geometry>
        <mesh filename="package://assets/mx_64t.stl"/>
      </geometry>
    </collision>
    <!-- Part mx_28 -->
    <collision>
      <origin xyz="0.10261 -0.0587923 0.420772" rpy="-1.5708 -1.5708 0"/>
      <geometry>
        <mesh filename="package://assets/mx_28.stl"/>
      </geometry>
    </collision>
    <!-- Part mx_28_2 -->
    <collision>
      <origin xyz="0.138292 0.046488 0.40748" rpy="-1.5708 -2.14948e-13 3.14159"/>
      <geometry>
        <mesh filename="package://assets/mx_28.stl"/>
      </geometry>
    </collision>
    <!-- Part mx_28_3 -->
    <collision>
      <origin xyz="0.189611 -0.0587923 0.404961" rpy="-1.5708 1.5708 0"/>
      <geometry>
        <mesh filename="package://assets/mx_28.stl"/>
      </geometry>
    </collision>
    <!-- Part upper_floor -->
    <collision>
      <origin xyz="0.0817323 -0.0369375 0.392066" rpy="-1.5708 1.12084e-14 -1.5708"/>
      <geometry>
        <mesh filename="package://assets/upper_floor.stl"/>
      </geometry>
    </collision>
    <!-- Part 2nd_floor -->
    <collision>
      <origin xyz="0.210488 -0.0369375 0.323066" rpy="1.5708 -1.14304e-14 1.5708"/>
      <geometry>
        <mesh filename="package://assets/2nd_floor.stl"/>
      </geometry>
    </collision>
    <!-- Part front_pillar -->
    <collision>
      <origin xyz="0.0741103 0.0720636 0.331066" rpy="1.5708 2.1517e-13 -6.55847e-15"/>
      <geometry>
        <mesh filename="package://assets/front_pillar.stl"/>
      </geometry>
    </collision>
    <!-- Part front_pillar_2 -->
    <collision>
      <origin xyz="0.21811 0.0650636 0.331066" rpy="1.5708 -2.1517e-13 3.14159"/>
      <geometry>
        <mesh filename="package://assets/front_pillar.stl"/>
      </geometry>
    </collision>
    <!-- Part front_pillar_3 -->
    <collision>
      <origin xyz="0.21811 -0.0449364 0.331066" rpy="1.5708 -2.15503e-13 3.14159"/>
      <geometry>
        <mesh filename="package://assets/front_pillar.stl"/>
      </geometry>
    </collision>
    <!-- Part front_pillar_4 -->
    <collision>
      <origin xyz="0.0741103 -0.0379364 0.384066" rpy="-1.5708 1.09239e-14 -1.5708"/>
      <geometry>
        <mesh filename="package://assets/front_pillar.stl"/>
      </geometry>
    </collision>
    <!-- Part pcnel_exch -->
    <collision>
      <origin xyz="0.14611 0.0115636 0.389066" rpy="-1.5708 1.09794e-14 -1.5708"/>
      <geometry>
        <mesh filename="package://assets/pcnel_exch.stl"/>
      </geometry>
    </collision>
    <!-- Part spacer_bracket_id_1_19_2_mir -->
    <collision>
      <origin xyz="0.182797 -0.0149836 0.409828" rpy="1.5708 -2.15281e-13 3.14159"/>
      <geometry>
        <mesh filename="package://assets/spacer_bracket_id_1_19_2_mir.stl"/>
      </geometry>
    </collision>
    <!-- Part handle_bracket_kidsize -->
    <collision>
      <origin xyz="0.21411 0.0343625 0.396066" rpy="-1.5708 1.12084e-14 -1.5708"/>
      <geometry>
        <mesh filename="package://assets/handle_bracket_kidsize.stl"/>
      </geometry>
    </collision>
    <!-- Part almi_5mm_bracket_servo_1_2_left -->
    <collision>
      <origin xyz="0.187247 -0.0197299 0.414929" rpy="1.5708 -2.15281e-13 3.14159"/>
      <geometry>
        <mesh filename="package://assets/almi_5mm_bracket_servo_1_2_left.stl"/>
      </geometry>
    </collision>
    <!-- Part handle -->
    <collision>
      <origin xyz="0.14611 0.0838625 0.449066" rpy="-3.14159 1.5708 0"/>
      <geometry>
        <mesh filename="package://assets/handle.stl"/>
      </geometry>
    </collision>
    <!-- Part holder_bumper_upper -->
    <collision>
      <origin xyz="0.079397 0.0879338 0.465317" rpy="1.5708 -2.15503e-13 3.14159"/>
      <geometry>
        <mesh filename="package://assets/holder_bumper_upper.stl"/>
      </geometry>
    </collision>
    <!-- Part handler_holder_siber -->
    <collision>
      <origin xyz="0.0876103 -0.0336375 0.354066" rpy="1.5708 -1.12084e-14 1.5708"/>
      <geometry>
        <mesh filename="package://assets/handler_holder_siber.stl"/>
      </geometry>
    </collision>
    <!-- Part bracket_1_2_lower_left -->
    <collision>
      <origin xyz="0.212597 -0.0199864 0.416614" rpy="1.5708 2.15281e-13 -6.33643e-15"/>
      <geometry>
        <mesh filename="package://assets/bracket_1_2_lower_left.stl"/>
      </geometry>
    </collision>
    <!-- Part front_upper_bumper -->
    <collision>
      <origin xyz="0.074897 -0.0655025 0.412466" rpy="1.5708 2.15503e-13 -6.33643e-15"/>
      <geometry>
        <mesh filename="package://assets/front_upper_bumper.stl"/>
      </geometry>
    </collision>
    <!-- Part petg_5_19_mx28_seating -->
    <collision>
      <origin xyz="0.158601 -0.0319025 0.399316" rpy="-1.5708 2.15392e-13 -6.33643e-15"/>
      <geometry>
        <mesh filename="package://assets/petg_5_19_mx28_seating.stl"/>
      </geometry>
    </collision>
    <!-- Part almi_5mm_bracket_servo_1_2 -->
    <collision>
      <origin xyz="0.104974 -0.0197299 0.414929" rpy="1.5708 2.15392e-13 -6.33643e-15"/>
      <geometry>
        <mesh filename="package://assets/almi_5mm_bracket_servo_1_2.stl"/>
      </geometry>
    </collision>
    <!-- Part spacer_bracket_id_1_19_2 -->
    <collision>
      <origin xyz="0.109424 -0.0149836 0.409828" rpy="1.5708 2.1517e-13 -6.33643e-15"/>
      <geometry>
        <mesh filename="package://assets/spacer_bracket_id_1_19_2.stl"/>
      </geometry>
    </collision>
    <!-- Part handler_holder_siber_2 -->
    <collision>
      <origin xyz="0.21461 -0.0336375 0.354066" rpy="1.5708 -1.12084e-14 1.5708"/>
      <geometry>
        <mesh filename="package://assets/handler_holder_siber.stl"/>
      </geometry>
    </collision>
    <!-- Part front_upper_bumper_mir -->
    <collision>
      <origin xyz="0.217097 -0.0655025 0.412466" rpy="1.5708 -2.15503e-13 3.14159"/>
      <geometry>
        <mesh filename="package://assets/front_upper_bumper_mir.stl"/>
      </geometry>
    </collision>
    <!-- Part handle_bracket_kidsize_2 -->
    <collision>
      <origin xyz="0.0781103 0.0343625 0.396066" rpy="-1.5708 9.8553e-15 -1.5708"/>
      <geometry>
        <mesh filename="package://assets/handle_bracket_kidsize.stl"/>
      </geometry>
    </collision>
    <!-- Part bracket_1_2_lower -->
    <collision>
      <origin xyz="0.0796235 -0.0199864 0.416614" rpy="1.5708 -2.15281e-13 3.14159"/>
      <geometry>
        <mesh filename="package://assets/bracket_1_2_lower.stl"/>
      </geometry>
    </collision>
    <!-- Part bumper_front_lower_mir -->
    <collision>
      <origin xyz="0.21461 -0.0681343 0.30103" rpy="1.5708 -2.14948e-13 3.14159"/>
      <geometry>
        <mesh filename="package://assets/bumper_front_lower_mir.stl"/>
      </geometry>
    </collision>
    <!-- Part spacer_106_64_mir2 -->
    <collision>
      <origin xyz="0.0982737 -0.0147932 0.313066" rpy="1.5708 -1.5708 0"/>
      <geometry>
        <mesh filename="package://assets/spacer_106_64_mir2.stl"/>
      </geometry>
    </collision>
    <!-- Part holder_lower_bracket_mir -->
    <collision>
      <origin xyz="0.186908 -0.0396343 0.342739" rpy="-1.5708 -2.14948e-13 3.14159"/>
      <geometry>
        <mesh filename="package://assets/holder_lower_bracket_mir.stl"/>
      </geometry>
    </collision>
    <!-- Part almi_2mm_floor_2nd__1 -->
    <collision>
      <origin xyz="0.142451 0.00981694 0.279066" rpy="6.55847e-15 1.5708 0"/>
      <geometry>
        <mesh filename="package://assets/almi_2mm_floor_2nd__1.stl"/>
      </geometry>
    </collision>
    <!-- Part spacer_106_64_mir2_mir -->
    <collision>
      <origin xyz="0.193947 -0.0147916 0.313066" rpy="-1.5708 -1.5708 0"/>
      <geometry>
        <mesh filename="package://assets/spacer_106_64_mir2_mir.stl"/>
      </geometry>
    </collision>
    <!-- Part back_bumper -->
    <collision>
      <origin xyz="0.21081 0.0545652 0.300066" rpy="1.5708 -1.14304e-14 1.5708"/>
      <geometry>
        <mesh filename="package://assets/back_bumper.stl"/>
      </geometry>
    </collision>
    <!-- Part xt_bracket -->
    <collision>
      <origin xyz="0.17691 0.0675652 0.279066" rpy="-1.14304e-14 -2.15281e-13 3.14159"/>
      <geometry>
        <mesh filename="package://assets/xt_bracket.stl"/>
      </geometry>
    </collision>
    <!-- Part battery_holder -->
    <collision>
      <origin xyz="0.14611 -0.0444348 0.274066" rpy="1.5708 -1.14304e-14 1.5708"/>
      <geometry>
        <mesh filename="package://assets/battery_holder.stl"/>
      </geometry>
    </collision>
    <!-- Part back_bumper_2 -->
    <collision>
      <origin xyz="0.0814103 0.0545652 0.300066" rpy="-1.5708 -1.14304e-14 1.5708"/>
      <geometry>
        <mesh filename="package://assets/back_bumper.stl"/>
      </geometry>
    </collision>
    <!-- Part bracket_back_bumper -->
    <collision>
      <origin xyz="0.19131 0.0565652 0.301066" rpy="1.5708 -2.15281e-13 3.14159"/>
      <geometry>
        <mesh filename="package://assets/bracket_back_bumper.stl"/>
      </geometry>
    </collision>
    <!-- Part holder_lower_bracket -->
    <collision>
      <origin xyz="0.105313 -0.0396359 0.342739" rpy="-1.5708 2.15281e-13 -6.55847e-15"/>
      <geometry>
        <mesh filename="package://assets/holder_lower_bracket.stl"/>
      </geometry>
    </collision>
    <!-- Part xt_bracket_2 -->
    <collision>
      <origin xyz="0.11531 0.0635652 0.279066" rpy="1.14304e-14 2.1517e-13 -6.55847e-15"/>
      <geometry>
        <mesh filename="package://assets/xt_bracket.stl"/>
      </geometry>
    </collision>
    <!-- Part bumper_front_lower -->
    <collision>
      <origin xyz="0.0776103 -0.0681359 0.30103" rpy="1.5708 2.15281e-13 -6.55847e-15"/>
      <geometry>
        <mesh filename="package://assets/bumper_front_lower.stl"/>
      </geometry>
    </collision>
    <!-- Part bracket_back_bumper_mir -->
    <collision>
      <origin xyz="0.10091 0.0565652 0.301066" rpy="1.5708 2.1517e-13 -6.50154e-15"/>
      <geometry>
        <mesh filename="package://assets/bracket_back_bumper_mir.stl"/>
      </geometry>
    </collision>
    <!-- Part torso_kidsize25_parts -->
    <visual>
      <origin xyz="0.146105 0.00568445 0.349252" rpy="0 -0 0"/>
      <geometry>
        <mesh filename="package://assets/merged/torso_kidsize25_visual.stl"/>
      </geometry>
      <material name="torso_kidsize25_parts_material">
        <color rgba="0.55972 0.560028 0.558638 1"/>
      </material>
    </visual>
  </link>
  <!-- Link neck -->
  <link name="neck">
    <inertial>
      <origin xyz="2.39298e-07 2.10142e-18 0.00879985" rpy="0 0 0"/>
      <mass value="0.0128985"/>
      <inertia ixx="5.01235e-06" ixy="2.63324e-11" ixz="-9.38605e-13" iyy="2.39998e-06" iyz="-2.11758e-21" izz="4.13467e-06"/>
    </inertial>
    <!-- Part almi_4mm_neck_bracket -->
    <collision>
      <origin xyz="0.0128945 -0.0185 0" rpy="1.5708 -0 -6.26583e-31"/>
      <geometry>
        <mesh filename="package://assets/almi_4mm_neck_bracket.stl"/>
      </geometry>
    </collision>
    <!-- Part carbon_2mm_neck_side_plate -->
    <collision>
      <origin xyz="5e-07 -0.0205 0.02" rpy="1.5708 -2.36658e-29 4.10658e-30"/>
      <geometry>
        <mesh filename="package://assets/carbon_2mm_neck_side_plate.stl"/>
      </geometry>
    </collision>
    <!-- Part carbon_2mm_neck_side_plate_2 -->
    <collision>
      <origin xyz="-3.46945e-17 0.0225 0.02" rpy="1.5708 -4.73317e-30 -1.00929e-29"/>
      <geometry>
        <mesh filename="package://assets/carbon_2mm_neck_side_plate.stl"/>
      </geometry>
    </collision>
    <!-- Part neck_parts -->
    <visual>
      <origin xyz="2.39298e-07 0 0.00879985" rpy="-1.12084e-14 -2.15281e-13 -1.5708"/>
      <geometry>
        <mesh filename="package://assets/merged/neck_visual.stl"/>
      </geometry>
      <material name="neck_parts_material">
        <color rgba="0.55972 0.560028 0.558638 1"/>
      </material>
    </visual>
  </link>
  <!-- Link head -->
  <link name="head">
    <inertial>
      <origin xyz="0.0315459 -0.00214801 0.0205645" rpy="0 0 0"/>
      <mass value="0.371554"/>
      <inertia ixx="0.000238323" ixy="4.47308e-05" ixz="-2.28198e-07" iyy="0.000308835" iyz="-2.79152e-07" izz="0.000217343"/>
    </inertial>
    <!-- Part petg_2mm_headbracket_old -->
    <collision>
      <origin xyz="-0.0064 0.0265 0.0386" rpy="1.5708 1.5708 0"/>
      <geometry>
        <mesh filename="package://assets/petg_2mm_headbracket_old.stl"/>
      </geometry>
    </collision>
    <!-- Part camera_logitech_c920_offset_2mm -->
    <collision>
      <origin xyz="0.0256 0.00182638 0.06759" rpy="1.5708 1.5708 0"/>
      <geometry>
        <mesh filename="package://assets/camera_logitech_c920_offset_2mm.stl"/>
      </geometry>
    </collision>
    <!-- Part camera_frame -->
    <collision>
      <origin xyz="0.0251 -0.0215 0.0535485" rpy="3.14159 1.3375e-27 1.5708"/>
      <geometry>
        <mesh filename="package://assets/camera_frame.stl"/>
      </geometry>
    </collision>
    <!-- Part mx_28_4 -->
    <collision>
      <origin xyz="0.0079054 0.0653899 0.0287863" rpy="1.5708 -0 0"/>
      <geometry>
        <mesh filename="package://assets/mx_28.stl"/>
      </geometry>
    </collision>
    <!-- Part petg_2mm_rotatingheadbracket -->
    <collision>
      <origin xyz="-0.0064 0.0265 0.0386" rpy="1.5708 1.5708 0"/>
      <geometry>
        <mesh filename="package://assets/petg_2mm_rotatingheadbracket.stl"/>
      </geometry>
    </collision>
    <!-- Part head_parts -->
    <visual>
      <origin xyz="0.0315459 -0.00214801 0.0205645" rpy="-5.50254e-14 1.5708 0"/>
      <geometry>
        <mesh filename="package://assets/merged/head_visual.stl"/>
      </geometry>
      <material name="head_parts_material">
        <color rgba="0.55972 0.560028 0.558638 1"/>
      </material>
    </visual>
  </link>
  <!-- Joint from neck to head -->
  <joint name="neck_pitch" type="revolute">
    <origin xyz="5e-07 -0.0205 0.037" rpy="-1.5708 -1.5708 0"/>
    <parent link="neck"/>
    <child link="head"/>
    <axis xyz="0 0 1"/>
    <limit effort="6" velocity="6.6" lower="-1.5708" upper="0.392699"/>
  </joint>
  <!-- Joint from torso_kidsize25 to neck -->
  <joint name="neck_yaw" type="revolute">
    <origin xyz="0.146197 -0.0189018 0.436266" rpy="2.15281e-13 -1.12084e-14 1.5708"/>
    <parent link="torso_kidsize25"/>
    <child link="neck"/>
    <axis xyz="0 0 1"/>
    <limit effort="6" velocity="6.6" lower="-3.14159" upper="3.14159"/>
  </joint>
  <!-- Link almi2_view_6_7__arm_bracket -->
  <link name="almi2_view_6_7__arm_bracket">
    <inertial>
      <origin xyz="-9.36751e-17 -0.00223841 0.00829596" rpy="0 0 0"/>
      <mass value="0.0151289"/>
      <inertia ixx="2.57897e-06" ixy="-3.24106e-38" ixz="-6.75078e-37" iyy="5.57377e-06" iyz="4.04961e-07" izz="5.85595e-06"/>
    </inertial>
    <!-- Part almi2_view_6_7__arm_bracket -->
    <collision>
      <origin xyz="0.0185 0.012 0.002" rpy="-1.5708 8.00338e-32 0"/>
      <geometry>
        <mesh filename="package://assets/almi2_view_6_7__arm_bracket.stl"/>
      </geometry>
    </collision>
    <!-- Part almi2_view_6_7__arm_bracket_parts -->
    <visual>
      <origin xyz="-9.54098e-17 -0.00223841 0.00829596" rpy="-1.5708 1.5708 0"/>
      <geometry>
        <mesh filename="package://assets/merged/almi2_view_6_7__arm_bracket_visual.stl"/>
      </geometry>
      <material name="almi2_view_6_7__arm_bracket_parts_material">
        <color rgba="0.55972 0.560028 0.558638 1"/>
      </material>
    </visual>
  </link>
  <!-- Link right_upperhand -->
  <link name="right_upperhand">
    <inertial>
      <origin xyz="-4.16556e-05 0.0497057 0.0229115" rpy="0 0 0"/>
      <mass value="0.178"/>
      <inertia ixx="0.000293103" ixy="7.35413e-07" ixz="2.0111e-08" iyy="3.4849e-05" iyz="-1.67161e-05" izz="0.00029267"/>
    </inertial>
    <!-- Part mx_28_5 -->
    <collision>
      <origin xyz="0.00818918 0.0341201 0.0335054" rpy="-1.5708 -1.5708 0"/>
      <geometry>
        <mesh filename="package://assets/mx_28.stl"/>
      </geometry>
    </collision>
    <!-- Part mx_28_6 -->
    <collision>
      <origin xyz="0.0079054 0.0653899 0.0287863" rpy="1.5708 -0 0"/>
      <geometry>
        <mesh filename="package://assets/mx_28.stl"/>
      </geometry>
    </collision>
    <!-- Part almi2_view_13__14__arm -->
    <collision>
      <origin xyz="-0.0819971 0.058605 0.0256" rpy="3.14159 1.11022e-16 -5.90699e-27"/>
      <geometry>
        <mesh filename="package://assets/almi2_view_13__14__arm.stl"/>
      </geometry>
    </collision>
    <!-- Part right_upperhand_parts -->
    <visual>
      <origin xyz="-4.16556e-05 0.0497057 0.0229115" rpy="1.5708 -6.44745e-15 -1.5708"/>
      <geometry>
        <mesh filename="package://assets/merged/right_upperhand_visual.stl"/>
      </geometry>
      <material name="right_upperhand_parts_material">
        <color rgba="0.55972 0.560028 0.558638 1"/>
      </material>
    </visual>
  </link>
  <!-- Link right_lowerhand -->
  <link name="right_lowerhand">
    <inertial>
      <origin xyz="-0.00130389 0.103918 -0.0103596" rpy="0 0 0"/>
      <mass value="0.149258"/>
      <inertia ixx="0.000225269" ixy="7.02224e-06" ixz="1.20544e-07" iyy="5.61474e-05" iyz="-3.26703e-05" izz="0.000240431"/>
    </inertial>
    <!-- Part almi_4_5mm_connector_lower_arm_kidsize -->
    <collision>
      <origin xyz="0.00225 0.0405 0" rpy="-1.5708 -1.11022e-16 3.14159"/>
      <geometry>
        <mesh filename="package://assets/almi_4_5mm_connector_lower_arm_kidsize.stl"/>
      </geometry>
    </collision>
    <!-- Part carbon_2mm_arm_kidsize_1 -->
    <collision>
      <origin xyz="0 0 0" rpy="-1.5708 -1.5708 0"/>
      <geometry>
        <mesh filename="package://assets/carbon_2mm_arm_kidsize_1.stl"/>
      </geometry>
    </collision>
    <!-- Part tpu_arm_kidsize_telapak -->
    <collision>
      <origin xyz="2.60209e-17 0.14 -0.0728" rpy="-1.5708 1.11022e-16 -4.9013e-29"/>
      <geometry>
        <mesh filename="package://assets/tpu_arm_kidsize_telapak.stl"/>
      </geometry>
    </collision>
    <!-- Part carbon_2mm_arm_kidsize_2 -->
    <collision>
      <origin xyz="2.94903e-17 -7.63278e-17 -0.043" rpy="3.14159 -1.5708 0"/>
      <geometry>
        <mesh filename="package://assets/carbon_2mm_arm_kidsize_2.stl"/>
      </geometry>
    </collision>
    <!-- Part right_lowerhand_parts -->
    <visual>
      <origin xyz="-0.00130389 0.103918 -0.0103596" rpy="-1.09725e-14 -8.42749e-14 -1.5708"/>
      <geometry>
        <mesh filename="package://assets/merged/right_lowerhand_visual.stl"/>
      </geometry>
      <material name="right_lowerhand_parts_material">
        <color rgba="0.55972 0.560028 0.558638 1"/>
      </material>
    </visual>
  </link>
  <!-- Joint from right_upperhand to right_lowerhand -->
  <joint name="right_elbow" type="revolute">
    <origin xyz="-0.0205971 0.09951 0.0256" rpy="-5.89437e-27 -1.5708 0"/>
    <parent link="right_upperhand"/>
    <child link="right_lowerhand"/>
    <axis xyz="0 0 1"/>
    <limit effort="6" velocity="6.6" lower="-2.35619" upper="2.35619"/>
  </joint>
  <!-- Joint from almi2_view_6_7__arm_bracket to right_upperhand -->
  <joint name="right_shoulder_roll" type="revolute">
    <origin xyz="0.0205 -0.0147498 0.0268034" rpy="1.5708 1.30895e-13 -1.5708"/>
    <parent link="almi2_view_6_7__arm_bracket"/>
    <child link="right_upperhand"/>
    <axis xyz="0 0 1"/>
    <limit effort="6" velocity="6.6" lower="-2.35619" upper="0.785398"/>
  </joint>
  <!-- Joint from torso_kidsize25 to almi2_view_6_7__arm_bracket -->
  <joint name="right_shoulder_pitch" type="revolute">
    <origin xyz="0.0738235 0.0065975 0.412866" rpy="1.5708 1.08614e-14 -1.5708"/>
    <parent link="torso_kidsize25"/>
    <child link="almi2_view_6_7__arm_bracket"/>
    <axis xyz="0 0 1"/>
    <limit effort="6" velocity="6.6" lower="-3.14159" upper="3.14159"/>
  </joint>
  <!-- Link almi2_view_6_7__arm_bracket_2 -->
  <link name="almi2_view_6_7__arm_bracket_2">
    <inertial>
      <origin xyz="-9.36751e-17 -0.00223841 0.00829596" rpy="0 0 0"/>
      <mass value="0.0151289"/>
      <inertia ixx="2.57897e-06" ixy="-1.13759e-37" ixz="-2.36947e-36" iyy="5.57377e-06" iyz="4.04961e-07" izz="5.85595e-06"/>
    </inertial>
    <!-- Part almi2_view_6_7__arm_bracket_2 -->
    <collision>
      <origin xyz="0.0185 0.012 0.002" rpy="-1.5708 2.80912e-31 0"/>
      <geometry>
        <mesh filename="package://assets/almi2_view_6_7__arm_bracket.stl"/>
      </geometry>
    </collision>
    <!-- Part almi2_view_6_7__arm_bracket_2_parts -->
    <visual>
      <origin xyz="-9.54098e-17 -0.00223841 0.00829596" rpy="-1.5708 -1.5708 0"/>
      <geometry>
        <mesh filename="package://assets/merged/almi2_view_6_7__arm_bracket_2_visual.stl"/>
      </geometry>
      <material name="almi2_view_6_7__arm_bracket_2_parts_material">
        <color rgba="0.55972 0.560028 0.558638 1"/>
      </material>
    </visual>
  </link>
  <!-- Link left_upperhand -->
  <link name="left_upperhand">
    <inertial>
      <origin xyz="-0.0497057 4.16564e-05 0.0182021" rpy="0 0 0"/>
      <mass value="0.178"/>
      <inertia ixx="3.47766e-05" ixy="7.35406e-07" ixz="-1.52286e-05" iyy="0.00029303" iyz="1.94701e-08" izz="0.00029267"/>
    </inertial>
    <!-- Part mx_28_7 -->
    <collision>
      <origin xyz="-0.0341201 -0.00818918 0.0076946" rpy="-3.14159 1.5708 0"/>
      <geometry>
        <mesh filename="package://assets/mx_28.stl"/>
      </geometry>
    </collision>
    <!-- Part almi2_view_13__14__arm_2 -->
    <collision>
      <origin xyz="-0.058605 0.0819971 0.0156" rpy="-3.90544e-30 -3.33067e-16 -1.5708"/>
      <geometry>
        <mesh filename="package://assets/almi2_view_13__14__arm.stl"/>
      </geometry>
    </collision>
    <!-- Part mx_28_8 -->
    <collision>
      <origin xyz="-0.0653899 0.0079054 0.0287863" rpy="1.5708 -1.11022e-16 1.5708"/>
      <geometry>
        <mesh filename="package://assets/mx_28.stl"/>
      </geometry>
    </collision>
    <!-- Part left_upperhand_parts -->
    <visual>
      <origin xyz="-0.0497057 4.16564e-05 0.0182021" rpy="1.5708 -6.33643e-15 3.14159"/>
      <geometry>
        <mesh filename="package://assets/merged/left_upperhand_visual.stl"/>
      </geometry>
      <material name="left_upperhand_parts_material">
        <color rgba="0.55972 0.560028 0.558638 1"/>
      </material>
    </visual>
  </link>
  <!-- Link left_lowerhand -->
  <link name="left_lowerhand">
    <inertial>
      <origin xyz="-0.00130389 0.103918 -0.0103596" rpy="0 0 0"/>
      <mass value="0.149258"/>
      <inertia ixx="0.000225269" ixy="7.02224e-06" ixz="1.20544e-07" iyy="5.61474e-05" iyz="-3.26703e-05" izz="0.000240431"/>
    </inertial>
    <!-- Part carbon_2mm_arm_kidsize_1_2 -->
    <collision>
      <origin xyz="-1.82146e-17 0 1.11022e-16" rpy="-1.5708 -1.5708 0"/>
      <geometry>
        <mesh filename="package://assets/carbon_2mm_arm_kidsize_1.stl"/>
      </geometry>
    </collision>
    <!-- Part tpu_arm_kidsize_telapak_2 -->
    <collision>
      <origin xyz="5.94143e-17 0.14 -0.0728" rpy="-1.5708 1.11022e-16 -7.07767e-16"/>
      <geometry>
        <mesh filename="package://assets/tpu_arm_kidsize_telapak.stl"/>
      </geometry>
    </collision>
    <!-- Part almi_4_5mm_connector_lower_arm_kidsize_2 -->
    <collision>
      <origin xyz="0.00225 0.0405 0" rpy="-1.5708 -1.11022e-16 3.14159"/>
      <geometry>
        <mesh filename="package://assets/almi_4_5mm_connector_lower_arm_kidsize.stl"/>
      </geometry>
    </collision>
    <!-- Part carbon_2mm_arm_kidsize_2_2 -->
    <collision>
      <origin xyz="-1.18178e-16 5.55112e-17 -0.043" rpy="3.14159 -1.5708 0"/>
      <geometry>
        <mesh filename="package://assets/carbon_2mm_arm_kidsize_2.stl"/>
      </geometry>
    </collision>
    <!-- Part left_lowerhand_parts -->
    <visual>
      <origin xyz="-0.00130389 0.103918 -0.0103596" rpy="-1.05839e-14 -9.63764e-14 1.5708"/>
      <geometry>
        <mesh filename="package://assets/merged/left_lowerhand_visual.stl"/>
      </geometry>
      <material name="left_lowerhand_parts_material">
        <color rgba="0.55972 0.560028 0.558638 1"/>
      </material>
    </visual>
  </link>
  <!-- Joint from left_upperhand to left_lowerhand -->
  <joint name="left_elbow" type="revolute">
    <origin xyz="-0.09951 0.0205971 0.0156" rpy="-1.5708 1.5708 0"/>
    <parent link="left_upperhand"/>
    <child link="left_lowerhand"/>
    <axis xyz="0 0 1"/>
    <limit effort="6" velocity="6.6" lower="-2.35619" upper="2.35619"/>
  </joint>
  <!-- Joint from almi2_view_6_7__arm_bracket_2 to left_upperhand -->
  <joint name="left_shoulder_roll" type="revolute">
    <origin xyz="-0.0205 -0.0147498 0.0268034" rpy="-0 1.5708 0"/>
    <parent link="almi2_view_6_7__arm_bracket_2"/>
    <child link="left_upperhand"/>
    <axis xyz="0 0 1"/>
    <limit effort="6" velocity="6.6" lower="-0.785398" upper="2.35619"/>
  </joint>
  <!-- Joint from torso_kidsize25 to almi2_view_6_7__arm_bracket_2 -->
  <joint name="left_shoulder_pitch" type="revolute">
    <origin xyz="0.218397 0.0065975 0.412866" rpy="1.5708 -1.05839e-14 1.5708"/>
    <parent link="torso_kidsize25"/>
    <child link="almi2_view_6_7__arm_bracket_2"/>
    <axis xyz="0 0 1"/>
    <limit effort="6" velocity="6.6" lower="-3.14159" upper="3.14159"/>
  </joint>
  <!-- Link stainless_steel_2mm_upper_leg_bracket -->
  <link name="stainless_steel_2mm_upper_leg_bracket">
    <inertial>
      <origin xyz="-0.00421162 1.80642e-07 0.00839045" rpy="0 0 0"/>
      <mass value="0.0521561"/>
      <inertia ixx="1.13163e-05" ixy="2.66522e-10" ixz="2.03733e-07" iyy="2.97089e-05" iyz="3.66542e-11" izz="2.98236e-05"/>
    </inertial>
    <!-- Part stainless_steel_2mm_upper_leg_bracket -->
    <collision>
      <origin xyz="-0.03298 -0.016 -5.55112e-17" rpy="0 -0 -2.99322e-31"/>
      <geometry>
        <mesh filename="package://assets/stainless_steel_2mm_upper_leg_bracket.stl"/>
      </geometry>
    </collision>
    <!-- Part stainless_steel_2mm_upper_leg_bracket_parts -->
    <visual>
      <origin xyz="-0.00421162 1.80642e-07 0.00839045" rpy="3.14159 2.15281e-13 -1.5708"/>
      <geometry>
        <mesh filename="package://assets/merged/stainless_steel_2mm_upper_leg_bracket_visual.stl"/>
      </geometry>
      <material name="stainless_steel_2mm_upper_leg_bracket_parts_material">
        <color rgba="0.55972 0.560028 0.558638 1"/>
      </material>
    </visual>
  </link>
  <!-- Link foot_right_1 -->
  <link name="foot_right_1">
    <inertial>
      <origin xyz="-0.000123356 0.0142848 -0.0039917" rpy="0 0 0"/>
      <mass value="0.288767"/>
      <inertia ixx="0.000301213" ixy="2.06889e-07" ixz="-7.68993e-07" iyy="0.000261184" iyz="-1.25332e-05" izz="0.000110844"/>
    </inertial>
    <!-- Part mx_64t_2 -->
    <collision>
      <origin xyz="1.38778e-17 0 0.0235" rpy="3.14159 -3.82774e-32 0"/>
      <geometry>
        <mesh filename="package://assets/mx_64t_2.stl"/>
      </geometry>
    </collision>
    <!-- Part almi_2mm_fr05_f101k_set -->
    <collision>
      <origin xyz="-1.38778e-17 5.55112e-17 -0.04958" rpy="1.5708 9.11923e-28 -1.5708"/>
      <geometry>
        <mesh filename="package://assets/almi_2mm_fr05_f101k_set.stl"/>
      </geometry>
    </collision>
    <!-- Part almi_2mm_connector_mx64 -->
    <collision>
      <origin xyz="-0.019 0.043 -0.01058" rpy="3.14159 6.31089e-30 1.5708"/>
      <geometry>
        <mesh filename="package://assets/almi_2mm_connector_mx64.stl"/>
      </geometry>
    </collision>
    <!-- Part almi_2mm_connector_mx64_2 -->
    <collision>
      <origin xyz="0.019 0.015 -0.01058" rpy="-3.14159 -6.31089e-30 -1.5708"/>
      <geometry>
        <mesh filename="package://assets/almi_2mm_connector_mx64.stl"/>
      </geometry>
    </collision>
    <!-- Part fr05_f101k_set -->
    <collision>
      <origin xyz="-2.91434e-16 0 -0.04938" rpy="3.14159 -9.11923e-28 1.5708"/>
      <geometry>
        <mesh filename="package://assets/fr05_f101k_set.stl"/>
      </geometry>
    </collision>
    <!-- Part mx_64t_2_2 -->
    <collision>
      <origin xyz="1.38778e-17 5.55112e-17 -0.02558" rpy="-3.14159 -1.5708 0"/>
      <geometry>
        <mesh filename="package://assets/mx_64t_2.stl"/>
      </geometry>
    </collision>
    <!-- Part mf128zz_1 -->
    <collision>
      <origin xyz="-2.77556e-16 0 -0.0516" rpy="-1.5708 9.11923e-28 -1.5708"/>
      <geometry>
        <mesh filename="package://assets/mf128zz_1.stl"/>
      </geometry>
    </collision>
    <!-- Part rx64_cap_1 -->
    <collision>
      <origin xyz="-2.63678e-16 -2.77556e-17 -0.05508" rpy="-3.14159 8.99301e-28 -1.5708"/>
      <geometry>
        <mesh filename="package://assets/rx64_cap_1.stl"/>
      </geometry>
    </collision>
    <!-- Part hn05_i101_1 -->
    <collision>
      <origin xyz="-2.498e-16 0 -0.05532" rpy="-1.5708 9.04035e-28 -1.5708"/>
      <geometry>
        <mesh filename="package://assets/hn05_i101_1.stl"/>
      </geometry>
    </collision>
    <!-- Part rx64_cap_1_2 -->
    <collision>
      <origin xyz="-0.0232 5.55112e-17 -0.02558" rpy="1.88064e-27 -1.5708 0"/>
      <geometry>
        <mesh filename="package://assets/rx64_cap_1.stl"/>
      </geometry>
    </collision>
    <!-- Part hn05_i101_1_2 -->
    <collision>
      <origin xyz="-0.02344 2.77556e-17 -0.02558" rpy="1.5708 -1.5708 0"/>
      <geometry>
        <mesh filename="package://assets/hn05_i101_1.stl"/>
      </geometry>
    </collision>
    <!-- Part mf128zz_1_2 -->
    <collision>
      <origin xyz="-0.01972 2.77556e-17 -0.02558" rpy="1.5708 -1.5708 0"/>
      <geometry>
        <mesh filename="package://assets/mf128zz_1.stl"/>
      </geometry>
    </collision>
    <!-- Part foot_right_1_parts -->
    <visual>
      <origin xyz="-0.000123356 0.0142848 -0.0039917" rpy="1.5708 -5.82295e-15 -9.22685e-14"/>
      <geometry>
        <mesh filename="package://assets/merged/foot_right_1_visual.stl"/>
      </geometry>
      <material name="foot_right_1_parts_material">
        <color rgba="0.55972 0.560028 0.558638 1"/>
      </material>
    </visual>
  </link>
  <!-- Link foot_right_2 -->
  <link name="foot_right_2">
    <inertial>
      <origin xyz="0.00374511 0.0598831 -0.0241672" rpy="0 0 0"/>
      <mass value="0.13801"/>
      <inertia ixx="0.000256725" ixy="-1.18271e-05" ixz="-3.44867e-07" iyy="9.86055e-05" iyz="6.82503e-06" izz="0.000188377"/>
    </inertial>
    <!-- Part stainless_steel_2mm__femur -->
    <collision>
      <origin xyz="-0.014 0.07746 -0.047" rpy="-1.5708 8.32667e-17 4.85723e-17"/>
      <geometry>
        <mesh filename="package://assets/stainless_steel_2mm__femur.stl"/>
      </geometry>
    </collision>
    <!-- Part stainless_steel_2mm__femur_2 -->
    <collision>
      <origin xyz="-0.014 0.07746 0.003" rpy="-1.5708 -8.73155e-32 0"/>
      <geometry>
        <mesh filename="package://assets/stainless_steel_2mm__femur.stl"/>
      </geometry>
    </collision>
    <!-- Part almi_6_5mm_l_mx64 -->
    <collision>
      <origin xyz="-0.0134121 0.0859 -0.047" rpy="1.5708 -2.77556e-16 -3.14159"/>
      <geometry>
        <mesh filename="package://assets/almi_6_5mm_l_mx64.stl"/>
      </geometry>
    </collision>
    <!-- Part almi_6_5mm_l_mx64_2 -->
    <collision>
      <origin xyz="-0.0134121 0.0859 -0.0065" rpy="1.5708 -7.21645e-16 -3.14159"/>
      <geometry>
        <mesh filename="package://assets/almi_6_5mm_l_mx64.stl"/>
      </geometry>
    </collision>
    <!-- Part mx_64t_1 -->
    <collision>
      <origin xyz="-6.45317e-16 0.134 -0.0235" rpy="2.08167e-16 7.21645e-16 6.52256e-16"/>
      <geometry>
        <mesh filename="package://assets/mx_64t_1.stl"/>
      </geometry>
    </collision>
    <!-- Part hn05_i101 -->
    <collision>
      <origin xyz="-5.93275e-16 0.134 -0.04694" rpy="-1.5708 8.88178e-16 1.5708"/>
      <geometry>
        <mesh filename="package://assets/hn05_i101.stl"/>
      </geometry>
    </collision>
    <!-- Part mf128zz -->
    <collision>
      <origin xyz="-6.14092e-16 0.134 -0.04322" rpy="-1.5708 9.15934e-16 1.5708"/>
      <geometry>
        <mesh filename="package://assets/mf128zz.stl"/>
      </geometry>
    </collision>
    <!-- Part rx64_cap -->
    <collision>
      <origin xyz="-6.21031e-16 0.134 -0.0467" rpy="-3.14159 -2.08167e-16 1.5708"/>
      <geometry>
        <mesh filename="package://assets/rx64_cap.stl"/>
      </geometry>
    </collision>
    <!-- Part foot_right_2_parts -->
    <visual>
      <origin xyz="0.00374511 0.0598831 -0.0241672" rpy="1.5708 -1.5708 0"/>
      <geometry>
        <mesh filename="package://assets/merged/foot_right_2_visual.stl"/>
      </geometry>
      <material name="foot_right_2_parts_material">
        <color rgba="0.55972 0.560028 0.558638 1"/>
      </material>
    </visual>
  </link>
  <!-- Link foot_right_3 -->
  <link name="foot_right_3">
    <inertial>
      <origin xyz="0.00350206 0.0535427 -0.0235017" rpy="0 0 0"/>
      <mass value="0.157154"/>
      <inertia ixx="0.000266743" ixy="8.33375e-06" ixz="5.26492e-09" iyy="0.000115972" iyz="-6.48605e-09" izz="0.000200186"/>
    </inertial>
    <!-- Part stainless_steel_2mm_leg_spacer -->
    <collision>
      <origin xyz="0.024 0.0190814 -0.045" rpy="-9.88536e-30 -2.22045e-16 1.5708"/>
      <geometry>
        <mesh filename="package://assets/stainless_steel_2mm_leg_spacer.stl"/>
      </geometry>
    </collision>
    <!-- Part stainless_steel_2mm_shinebone -->
    <collision>
      <origin xyz="0.0135 0.0197269 -0.05" rpy="1.5708 5.55112e-16 3.1225e-16"/>
      <geometry>
        <mesh filename="package://assets/stainless_steel_2mm_shinebone.stl"/>
      </geometry>
    </collision>
    <!-- Part stainless_steel_2mm_shinebone_2 -->
    <collision>
      <origin xyz="0.0135 0.0197269 1.38778e-17" rpy="1.5708 3.69832e-31 0"/>
      <geometry>
        <mesh filename="package://assets/stainless_steel_2mm_shinebone.stl"/>
      </geometry>
    </collision>
    <!-- Part foot_right_3_parts -->
    <visual>
      <origin xyz="0.00350206 0.0535427 -0.0235017" rpy="1.5708 -1.5708 0"/>
      <geometry>
        <mesh filename="package://assets/merged/foot_right_3_visual.stl"/>
      </geometry>
      <material name="foot_right_3_parts_material">
        <color rgba="0.55972 0.560028 0.558638 1"/>
      </material>
    </visual>
  </link>
  <!-- Link foot_right_4 -->
  <link name="foot_right_4">
    <inertial>
      <origin xyz="-0.0215978 0.0144558 0.0236219" rpy="0 0 0"/>
      <mass value="0.292143"/>
      <inertia ixx="0.000112946" ixy="1.25976e-05" ixz="-7.69336e-07" iyy="0.000262476" iyz="-2.05088e-07" izz="0.000302507"/>
    </inertial>
    <!-- Part mx_64t_3 -->
    <collision>
      <origin xyz="-0.04908 -3.64292e-17 0.0235" rpy="3.14159 -1.5708 0"/>
      <geometry>
        <mesh filename="package://assets/mx_64t_3.stl"/>
      </geometry>
    </collision>
    <!-- Part fr05_f101k_set_1 -->
    <collision>
      <origin xyz="0.024 4.58208e-05 0.0235" rpy="1.5708 -2.52435e-29 1.5708"/>
      <geometry>
        <mesh filename="package://assets/fr05_f101k_set_1.stl"/>
      </geometry>
    </collision>
    <!-- Part almi_2mm_connector_mx64_1 -->
    <collision>
      <origin xyz="-0.015 0.015 0.0425" rpy="-1.5708 -2.27192e-28 -1.5708"/>
      <geometry>
        <mesh filename="package://assets/almi_2mm_connector_mx64_1.stl"/>
      </geometry>
    </collision>
    <!-- Part almi_2mm_connector_mx64_1_2 -->
    <collision>
      <origin xyz="-0.015 0.043 0.0045" rpy="1.5708 -2.52435e-29 1.5708"/>
      <geometry>
        <mesh filename="package://assets/almi_2mm_connector_mx64_1.stl"/>
      </geometry>
    </collision>
    <!-- Part mx_64t_3_2 -->
    <collision>
      <origin xyz="3.46945e-18 0 0.0235" rpy="3.14159 2.18676e-31 0"/>
      <geometry>
        <mesh filename="package://assets/mx_64t_3.stl"/>
      </geometry>
    </collision>
    <!-- Part almi_2mm_fr05_f101k_set_1 -->
    <collision>
      <origin xyz="0.024 -5.20417e-18 0.0235" rpy="3.14159 2.52435e-29 -1.5708"/>
      <geometry>
        <mesh filename="package://assets/almi_2mm_fr05_f101k_set_1.stl"/>
      </geometry>
    </collision>
    <!-- Part hn05_i101_2 -->
    <collision>
      <origin xyz="4.51028e-17 6.93889e-18 0.04694" rpy="1.5708 -2.91434e-16 -7.63278e-17"/>
      <geometry>
        <mesh filename="package://assets/hn05_i101_2.stl"/>
      </geometry>
    </collision>
    <!-- Part mf128zz_2 -->
    <collision>
      <origin xyz="2.08167e-17 1.64799e-17 0.04322" rpy="1.5708 -2.08167e-16 -1.80411e-16"/>
      <geometry>
        <mesh filename="package://assets/mf128zz_2.stl"/>
      </geometry>
    </collision>
    <!-- Part rx64_cap_2 -->
    <collision>
      <origin xyz="1.73472e-17 2.86229e-17 0.0467" rpy="3.78653e-29 -2.35922e-16 6.93889e-17"/>
      <geometry>
        <mesh filename="package://assets/rx64_cap_2.stl"/>
      </geometry>
    </collision>
    <!-- Part mf128zz_2_2 -->
    <collision>
      <origin xyz="0.02622 4.58208e-05 0.0235" rpy="-3.14159 -2.52435e-29 1.5708"/>
      <geometry>
        <mesh filename="package://assets/mf128zz_2.stl"/>
      </geometry>
    </collision>
    <!-- Part hn05_i101_2_2 -->
    <collision>
      <origin xyz="0.02994 4.58208e-05 0.0235" rpy="-3.14159 -2.52435e-29 1.5708"/>
      <geometry>
        <mesh filename="package://assets/hn05_i101_2.stl"/>
      </geometry>
    </collision>
    <!-- Part rx64_cap_2_2 -->
    <collision>
      <origin xyz="0.0297 4.58208e-05 0.0235" rpy="1.5708 -5.04871e-29 1.5708"/>
      <geometry>
        <mesh filename="package://assets/rx64_cap_2.stl"/>
      </geometry>
    </collision>
    <!-- Part foot_right_4_parts -->
    <visual>
      <origin xyz="-0.0215978 0.0144558 0.0236219" rpy="-1.5708 1.5708 0"/>
      <geometry>
        <mesh filename="package://assets/merged/foot_right_4_visual.stl"/>
      </geometry>
      <material name="foot_right_4_parts_material">
        <color rgba="0.55972 0.560028 0.558638 1"/>
      </material>
    </visual>
  </link>
  <!-- Link foot_right_5 -->
  <link name="foot_right_5">
    <inertial>
      <origin xyz="-0.00431494 -0.027932 0.0410276" rpy="0 0 0"/>
      <mass value="0.132192"/>
      <inertia ixx="0.000177533" ixy="-1.91248e-06" ixz="5.63401e-06" iyy="0.000221544" iyz="8.6074e-07" izz="6.06598e-05"/>
    </inertial>
    <!-- Part pla_50__shoes -->
    <collision>
      <origin xyz="-0.04925 -0.032 0.10376" rpy="-2.27192e-28 -1.5708 0"/>
      <geometry>
        <mesh filename="package://assets/pla_50__shoes.stl"/>
      </geometry>
    </collision>
    <!-- Part almi_2mm_lower_leg -->
    <collision>
      <origin xyz="-0.00775 -0.032 0.02876" rpy="-3.14159 1.5708 0"/>
      <geometry>
        <mesh filename="package://assets/almi_2mm_lower_leg.stl"/>
      </geometry>
    </collision>
    <!-- Part stainless_steel_2mm_lower_leg_bracket -->
    <collision>
      <origin xyz="-0.016 -0.032 0.00052" rpy="-1.5708 -1.5708 0"/>
      <geometry>
        <mesh filename="package://assets/stainless_steel_2mm_lower_leg_bracket.stl"/>
      </geometry>
    </collision>
    <!-- Part foot_right_5_parts -->
    <visual>
      <origin xyz="-0.00431494 -0.027932 0.0410276" rpy="-1.5708 6.79439e-15 1.44754e-13"/>
      <geometry>
        <mesh filename="package://assets/merged/foot_right_5_visual.stl"/>
      </geometry>
      <material name="foot_right_5_parts_material">
        <color rgba="0.55972 0.560028 0.558638 1"/>
      </material>
    </visual>
  </link>
  <!-- Joint from foot_right_4 to foot_right_5 -->
  <joint name="right_ankle_roll" type="revolute">
    <origin xyz="-0.02558 -4.43135e-15 0.0235" rpy="2.06085e-15 1.5708 0"/>
    <parent link="foot_right_4"/>
    <child link="foot_right_5"/>
    <axis xyz="0 0 1"/>
    <limit effort="6" velocity="6.6" lower="-1.0472" upper="1.0472"/>
  </joint>
  <!-- Joint from foot_right_3 to foot_right_4 -->
  <joint name="right_ankle_pitch" type="revolute">
    <origin xyz="-1.11022e-16 0.111702 2.77556e-17" rpy="-3.14159 -1.44182e-29 -6.31382e-14"/>
    <parent link="foot_right_3"/>
    <child link="foot_right_4"/>
    <axis xyz="0 0 1"/>
    <limit effort="6" velocity="6.6" lower="-1.5708" upper="1.5708"/>
  </joint>
  <!-- Joint from foot_right_2 to foot_right_3 -->
  <joint name="right_knee" type="revolute">
    <origin xyz="-6.21031e-16 0.134 2.77556e-17" rpy="2.08167e-16 7.21645e-16 1.53223e-14"/>
    <parent link="foot_right_2"/>
    <child link="foot_right_3"/>
    <axis xyz="0 0 1"/>
    <limit effort="6" velocity="6.6" lower="-2.35619" upper="2.35619"/>
  </joint>
  <!-- Joint from foot_right_1 to foot_right_2 -->
  <joint name="right_hip_pitch" type="revolute">
    <origin xyz="0.0235 2.77556e-17 -0.02558" rpy="-1.88064e-27 1.5708 0"/>
    <parent link="foot_right_1"/>
    <child link="foot_right_2"/>
    <axis xyz="0 0 1"/>
    <limit effort="6" velocity="6.6" lower="-1.9635" upper="1.1781"/>
  </joint>
  <!-- Joint from stainless_steel_2mm_upper_leg_bracket to foot_right_1 -->
  <joint name="right_hip_roll" type="revolute">
    <origin xyz="-0.0335 -3.55965e-14 0.032" rpy="1.5708 1.23013e-13 -1.5708"/>
    <parent link="stainless_steel_2mm_upper_leg_bracket"/>
    <child link="foot_right_1"/>
    <axis xyz="0 0 1"/>
    <limit effort="6" velocity="6.6" lower="-0.785398" upper="1.5708"/>
  </joint>
  <!-- Joint from torso_kidsize25 to stainless_steel_2mm_upper_leg_bracket -->
  <joint name="right_hip_yaw" type="revolute">
    <origin xyz="0.0966103 0.0108641 0.272566" rpy="3.14159 1.14304e-14 -1.5708"/>
    <parent link="torso_kidsize25"/>
    <child link="stainless_steel_2mm_upper_leg_bracket"/>
    <axis xyz="0 0 1"/>
    <limit effort="6" velocity="6.6" lower="-1.5708" upper="0.785398"/>
  </joint>
  <!-- Link stainless_steel_2mm_upper_leg_bracket_mir -->
  <link name="stainless_steel_2mm_upper_leg_bracket_mir">
    <inertial>
      <origin xyz="-0.00421162 -1.80642e-07 0.00839045" rpy="0 0 0"/>
      <mass value="0.0521561"/>
      <inertia ixx="1.13163e-05" ixy="-2.66522e-10" ixz="2.03733e-07" iyy="2.97089e-05" iyz="-3.66542e-11" izz="2.98236e-05"/>
    </inertial>
    <!-- Part stainless_steel_2mm_upper_leg_bracket_mir -->
    <collision>
      <origin xyz="-0.03298 0.016 0" rpy="3.14159 -0 1.80849e-31"/>
      <geometry>
        <mesh filename="package://assets/stainless_steel_2mm_upper_leg_bracket_mir.stl"/>
      </geometry>
    </collision>
    <!-- Part stainless_steel_2mm_upper_leg_bracket_mir_parts -->
    <visual>
      <origin xyz="-0.00421162 -1.80642e-07 0.00839045" rpy="3.14159 2.1517e-13 -1.5708"/>
      <geometry>
        <mesh filename="package://assets/merged/stainless_steel_2mm_upper_leg_bracket_mir_visual.stl"/>
      </geometry>
      <material name="stainless_steel_2mm_upper_leg_bracket_mir_parts_material">
        <color rgba="0.55972 0.560028 0.558638 1"/>
      </material>
    </visual>
  </link>
  <!-- Link foot_left_1 -->
  <link name="foot_left_1">
    <inertial>
      <origin xyz="-0.000121924 -0.0144559 -0.00398223" rpy="0 0 0"/>
      <mass value="0.292143"/>
      <inertia ixx="0.000302507" ixy="-1.96526e-07" ixz="-7.69256e-07" iyy="0.000262475" iyz="1.25975e-05" izz="0.000112946"/>
    </inertial>
    <!-- Part mx_64t_mir_1 -->
    <collision>
      <origin xyz="0 0 0.0235" rpy="0 1.10898e-31 0"/>
      <geometry>
        <mesh filename="package://assets/mx_64t_mir_1.stl"/>
      </geometry>
    </collision>
    <!-- Part almi_2mm_fr05_f101k_set_mir -->
    <collision>
      <origin xyz="2.77556e-17 2.77556e-17 -0.04958" rpy="1.5708 -0 1.5708"/>
      <geometry>
        <mesh filename="package://assets/almi_2mm_fr05_f101k_set_mir.stl"/>
      </geometry>
    </collision>
    <!-- Part almi_2mm_connector_mx64_mir -->
    <collision>
      <origin xyz="-0.019 -0.043 -0.01058" rpy="-1.11022e-16 -0 -1.5708"/>
      <geometry>
        <mesh filename="package://assets/almi_2mm_connector_mx64_mir.stl"/>
      </geometry>
    </collision>
    <!-- Part fr05_f101k_set_mir -->
    <collision>
      <origin xyz="-2.22045e-16 -4.58208e-05 -0.04958" rpy="-2.22045e-16 -0 -1.5708"/>
      <geometry>
        <mesh filename="package://assets/fr05_f101k_set_mir.stl"/>
      </geometry>
    </collision>
    <!-- Part almi_2mm_connector_mx64_mir_2 -->
    <collision>
      <origin xyz="0.019 -0.015 -0.01058" rpy="1.11022e-16 2.46598e-27 1.5708"/>
      <geometry>
        <mesh filename="package://assets/almi_2mm_connector_mx64_mir.stl"/>
      </geometry>
    </collision>
    <!-- Part mx_64t_mir_1_2 -->
    <collision>
      <origin xyz="2.77556e-17 5.55112e-17 -0.02558" rpy="1.11022e-16 -1.5708 0"/>
      <geometry>
        <mesh filename="package://assets/mx_64t_mir_1.stl"/>
      </geometry>
    </collision>
    <!-- Part mf128zz_mir_1 -->
    <collision>
      <origin xyz="-2.498e-16 -4.58208e-05 -0.0518" rpy="-1.5708 -4.73317e-30 1.5708"/>
      <geometry>
        <mesh filename="package://assets/mf128zz_mir_1.stl"/>
      </geometry>
    </collision>
    <!-- Part hn05_i101_mir_1 -->
    <collision>
      <origin xyz="-2.22045e-16 -4.58208e-05 -0.05552" rpy="-1.5708 -0 1.5708"/>
      <geometry>
        <mesh filename="package://assets/hn05_i101_mir_1.stl"/>
      </geometry>
    </collision>
    <!-- Part rx64_cap_mir_1 -->
    <collision>
      <origin xyz="-2.22045e-16 -4.58208e-05 -0.05528" rpy="2.22045e-16 -6.31089e-30 1.5708"/>
      <geometry>
        <mesh filename="package://assets/rx64_cap_mir_1.stl"/>
      </geometry>
    </collision>
    <!-- Part rx64_cap_mir_1_2 -->
    <collision>
      <origin xyz="-0.0232 0 -0.02558" rpy="-1.5708 -7.88861e-30 -1.5708"/>
      <geometry>
        <mesh filename="package://assets/rx64_cap_mir_1.stl"/>
      </geometry>
    </collision>
    <!-- Part hn05_i101_mir_1_2 -->
    <collision>
      <origin xyz="-0.02344 0 -0.02558" rpy="3.14159 -0 -1.5708"/>
      <geometry>
        <mesh filename="package://assets/hn05_i101_mir_1.stl"/>
      </geometry>
    </collision>
    <!-- Part mf128zz_mir_1_2 -->
    <collision>
      <origin xyz="-0.01972 0 -0.02558" rpy="3.14159 -0 -1.5708"/>
      <geometry>
        <mesh filename="package://assets/mf128zz_mir_1.stl"/>
      </geometry>
    </collision>
    <!-- Part foot_left_1_parts -->
    <visual>
      <origin xyz="-0.000121924 -0.0144559 -0.00398223" rpy="1.5708 -5.79519e-15 3.14159"/>
      <geometry>
        <mesh filename="package://assets/merged/foot_left_1_visual.stl"/>
      </geometry>
      <material name="foot_left_1_parts_material">
        <color rgba="0.55972 0.560028 0.558638 1"/>
      </material>
    </visual>
  </link>
  <!-- Link foot_left_2 -->
  <link name="foot_left_2">
    <inertial>
      <origin xyz="0.00374511 -0.0598831 -0.0241672" rpy="0 0 0"/>
      <mass value="0.13801"/>
      <inertia ixx="0.000256725" ixy="1.18271e-05" ixz="-3.44867e-07" iyy="9.86055e-05" iyz="-6.82503e-06" izz="0.000188377"/>
    </inertial>
    <!-- Part mx_64t_mir -->
    <collision>
      <origin xyz="-6.2797e-16 -0.134 -0.0235" rpy="3.14159 -3.8896e-30 8.5197e-29"/>
      <geometry>
        <mesh filename="package://assets/mx_64t_mir.stl"/>
      </geometry>
    </collision>
    <!-- Part stainless_steel_2mm__femur_mir -->
    <collision>
      <origin xyz="-0.014 -0.07746 -0.047" rpy="-1.5708 -7.34157e-31 9.78188e-29"/>
      <geometry>
        <mesh filename="package://assets/stainless_steel_2mm__femur_mir.stl"/>
      </geometry>
    </collision>
    <!-- Part stainless_steel_2mm__femur_mir_2 -->
    <collision>
      <origin xyz="-0.014 -0.07746 0.003" rpy="-1.5708 5.47038e-32 0"/>
      <geometry>
        <mesh filename="package://assets/stainless_steel_2mm__femur_mir.stl"/>
      </geometry>
    </collision>
    <!-- Part almi_6_5mm_l_mx64_mir -->
    <collision>
      <origin xyz="-0.0134121 -0.0859 -0.0065" rpy="1.5708 -5.47038e-32 -3.14159"/>
      <geometry>
        <mesh filename="package://assets/almi_6_5mm_l_mx64_mir.stl"/>
      </geometry>
    </collision>
    <!-- Part almi_6_5mm_l_mx64_mir_2 -->
    <collision>
      <origin xyz="-0.0134121 -0.0859 -0.047" rpy="1.5708 -5.47038e-32 -3.14159"/>
      <geometry>
        <mesh filename="package://assets/almi_6_5mm_l_mx64_mir.stl"/>
      </geometry>
    </collision>
    <!-- Part hn05_i101_mir -->
    <collision>
      <origin xyz="-6.52256e-16 -0.134 -0.04694" rpy="-1.5708 -1.26218e-28 -1.5708"/>
      <geometry>
        <mesh filename="package://assets/hn05_i101_mir.stl"/>
      </geometry>
    </collision>
    <!-- Part rx64_cap_mir -->
    <collision>
      <origin xyz="-6.17562e-16 -0.134 -0.0467" rpy="-1.11022e-16 -1.13596e-28 -1.5708"/>
      <geometry>
        <mesh filename="package://assets/rx64_cap_mir.stl"/>
      </geometry>
    </collision>
    <!-- Part mf128zz_mir -->
    <collision>
      <origin xyz="-6.31439e-16 -0.134 -0.04322" rpy="-1.5708 -1.26218e-28 -1.5708"/>
      <geometry>
        <mesh filename="package://assets/mf128zz_mir.stl"/>
      </geometry>
    </collision>
    <!-- Part foot_left_2_parts -->
    <visual>
      <origin xyz="0.00374511 -0.0598831 -0.0241672" rpy="-1.5708 1.5708 0"/>
      <geometry>
        <mesh filename="package://assets/merged/foot_left_2_visual.stl"/>
      </geometry>
      <material name="foot_left_2_parts_material">
        <color rgba="0.55972 0.560028 0.558638 1"/>
      </material>
    </visual>
  </link>
  <!-- Link foot_left_3 -->
  <link name="foot_left_3">
    <inertial>
      <origin xyz="0.00350206 -0.0535427 -0.0235017" rpy="0 0 0"/>
      <mass value="0.157154"/>
      <inertia ixx="0.000266743" ixy="-8.33375e-06" ixz="5.26492e-09" iyy="0.000115972" iyz="6.48605e-09" izz="0.000200186"/>
    </inertial>
    <!-- Part stainless_steel_2mm_shinebone_mir -->
    <collision>
      <origin xyz="0.0135 -0.0197269 -0.05" rpy="1.5708 -4.44089e-16 -6.31089e-30"/>
      <geometry>
        <mesh filename="package://assets/stainless_steel_2mm_shinebone_mir.stl"/>
      </geometry>
    </collision>
    <!-- Part stainless_steel_2mm_leg_spacer_mir -->
    <collision>
      <origin xyz="0.024 -0.0190814 -0.045" rpy="3.14159 -0 -1.5708"/>
      <geometry>
        <mesh filename="package://assets/stainless_steel_2mm_leg_spacer_mir.stl"/>
      </geometry>
    </collision>
    <!-- Part stainless_steel_2mm_shinebone_mir_2 -->
    <collision>
      <origin xyz="0.0135 -0.0197269 0" rpy="1.5708 -3.51852e-31 0"/>
      <geometry>
        <mesh filename="package://assets/stainless_steel_2mm_shinebone_mir.stl"/>
      </geometry>
    </collision>
    <!-- Part foot_left_3_parts -->
    <visual>
      <origin xyz="0.00350206 -0.0535427 -0.0235017" rpy="-1.5708 1.5708 0"/>
      <geometry>
        <mesh filename="package://assets/merged/foot_left_3_visual.stl"/>
      </geometry>
      <material name="foot_left_3_parts_material">
        <color rgba="0.55972 0.560028 0.558638 1"/>
      </material>
    </visual>
  </link>
  <!-- Link foot_left_4 -->
  <link name="foot_left_4">
    <inertial>
      <origin xyz="-0.0215978 -0.0144559 0.0236219" rpy="0 0 0"/>
      <mass value="0.292143"/>
      <inertia ixx="0.000112946" ixy="-1.25975e-05" ixz="-7.69402e-07" iyy="0.000262475" iyz="2.05066e-07" izz="0.000302507"/>
    </inertial>
    <!-- Part mx_64t_mir_2 -->
    <collision>
      <origin xyz="-0.04908 -2.1684e-17 0.0235" rpy="-2.20881e-29 -1.5708 0"/>
      <geometry>
        <mesh filename="package://assets/mx_64t_mir_2.stl"/>
      </geometry>
    </collision>
    <!-- Part almi_2mm_connector_mx64_mir_1 -->
    <collision>
      <origin xyz="-0.015 -0.015 0.0425" rpy="-1.5708 -0 1.5708"/>
      <geometry>
        <mesh filename="package://assets/almi_2mm_connector_mx64_mir_1.stl"/>
      </geometry>
    </collision>
    <!-- Part fr05_f101k_set_mir_1 -->
    <collision>
      <origin xyz="0.024 -4.58208e-05 0.0235" rpy="1.5708 2.22045e-16 -1.5708"/>
      <geometry>
        <mesh filename="package://assets/fr05_f101k_set_mir_1.stl"/>
      </geometry>
    </collision>
    <!-- Part mx_64t_mir_2_2 -->
    <collision>
      <origin xyz="3.46945e-18 -8.67362e-19 0.0235" rpy="0 1.99604e-31 0"/>
      <geometry>
        <mesh filename="package://assets/mx_64t_mir_2.stl"/>
      </geometry>
    </collision>
    <!-- Part almi_2mm_fr05_f101k_set_mir_1 -->
    <collision>
      <origin xyz="0.024 1.99493e-17 0.0235" rpy="-2.22045e-16 -2.22045e-16 1.5708"/>
      <geometry>
        <mesh filename="package://assets/almi_2mm_fr05_f101k_set_mir_1.stl"/>
      </geometry>
    </collision>
    <!-- Part almi_2mm_connector_mx64_mir_1_2 -->
    <collision>
      <origin xyz="-0.015 -0.043 0.0045" rpy="1.5708 4.2914e-28 -1.5708"/>
      <geometry>
        <mesh filename="package://assets/almi_2mm_connector_mx64_mir_1.stl"/>
      </geometry>
    </collision>
    <!-- Part hn05_i101_mir_2 -->
    <collision>
      <origin xyz="6.93889e-18 1.21431e-17 0.04694" rpy="1.5708 9.88465e-31 0"/>
      <geometry>
        <mesh filename="package://assets/hn05_i101_mir_2.stl"/>
      </geometry>
    </collision>
    <!-- Part mf128zz_mir_2 -->
    <collision>
      <origin xyz="2.77556e-17 -6.07153e-18 0.04322" rpy="1.5708 1.77733e-30 0"/>
      <geometry>
        <mesh filename="package://assets/mf128zz_mir_2.stl"/>
      </geometry>
    </collision>
    <!-- Part rx64_cap_mir_2 -->
    <collision>
      <origin xyz="1.38778e-17 -2.34188e-17 0.0467" rpy="-3.14159 1.99604e-31 0"/>
      <geometry>
        <mesh filename="package://assets/rx64_cap_mir_2.stl"/>
      </geometry>
    </collision>
    <!-- Part mf128zz_mir_2_2 -->
    <collision>
      <origin xyz="0.02622 -4.58208e-05 0.0235" rpy="2.22045e-16 2.22045e-16 -1.5708"/>
      <geometry>
        <mesh filename="package://assets/mf128zz_mir_2.stl"/>
      </geometry>
    </collision>
    <!-- Part hn05_i101_mir_2_2 -->
    <collision>
      <origin xyz="0.02994 -4.58208e-05 0.0235" rpy="2.22045e-16 2.22045e-16 -1.5708"/>
      <geometry>
        <mesh filename="package://assets/hn05_i101_mir_2.stl"/>
      </geometry>
    </collision>
    <!-- Part rx64_cap_mir_2_2 -->
    <collision>
      <origin xyz="0.0297 -4.58208e-05 0.0235" rpy="1.5708 2.22045e-16 -1.5708"/>
      <geometry>
        <mesh filename="package://assets/rx64_cap_mir_2.stl"/>
      </geometry>
    </collision>
    <!-- Part foot_left_4_parts -->
    <visual>
      <origin xyz="-0.0215978 -0.0144559 0.0236219" rpy="1.5708 -1.5708 0"/>
      <geometry>
        <mesh filename="package://assets/merged/foot_left_4_visual.stl"/>
      </geometry>
      <material name="foot_left_4_parts_material">
        <color rgba="0.55972 0.560028 0.558638 1"/>
      </material>
    </visual>
  </link>
  <!-- Link foot_left_5 -->
  <link name="foot_left_5">
    <inertial>
      <origin xyz="-0.00577513 0.0300863 0.0389132" rpy="0 0 0"/>
      <mass value="0.229936"/>
      <inertia ixx="0.000336096" ixy="2.89074e-06" ixz="4.67383e-06" iyy="0.000437543" iyz="5.55837e-07" izz="0.000121048"/>
    </inertial>
    <!-- Part almi_2mm_lower_leg_mir -->
    <collision>
      <origin xyz="-0.00775 0.032 0.02876" rpy="-5.55112e-16 1.5708 0"/>
      <geometry>
        <mesh filename="package://assets/almi_2mm_lower_leg_mir.stl"/>
      </geometry>
    </collision>
    <!-- Part stainless_steel_2mm_lower_leg_bracket_mir -->
    <collision>
      <origin xyz="-0.016 0.032 0.00052" rpy="-1.5708 -1.5708 0"/>
      <geometry>
        <mesh filename="package://assets/stainless_steel_2mm_lower_leg_bracket_mir.stl"/>
      </geometry>
    </collision>
    <!-- Part pla_50__shoes_mir -->
    <collision>
      <origin xyz="-0.04925 0.032 0.10376" rpy="-3.14159 -1.5708 0"/>
      <geometry>
        <mesh filename="package://assets/pla_50__shoes_mir.stl"/>
      </geometry>
    </collision>
    <!-- Part foot_left_5_parts -->
    <visual>
      <origin xyz="-0.00577513 0.0300863 0.0389132" rpy="-1.5708 5.68417e-15 -3.14159"/>
      <geometry>
        <mesh filename="package://assets/merged/foot_left_5_visual.stl"/>
      </geometry>
      <material name="foot_left_5_parts_material">
        <color rgba="0.55972 0.560028 0.558638 1"/>
      </material>
    </visual>
  </link>
  <!-- Joint from foot_left_4 to foot_left_5 -->
  <joint name="left_ankle_roll" type="revolute">
    <origin xyz="-0.02558 6.93889e-18 0.0235" rpy="1.89327e-29 1.5708 0"/>
    <parent link="foot_left_4"/>
    <child link="foot_left_5"/>
    <axis xyz="0 0 1"/>
    <limit effort="6" velocity="6.6" lower="-1.0472" upper="1.0472"/>
  </joint>
  <!-- Joint from foot_left_3 to foot_left_4 -->
  <joint name="left_ankle_pitch" type="revolute">
    <origin xyz="-8.67362e-17 -0.111702 -5.55112e-17" rpy="3.14159 -3.35505e-30 -1.16573e-15"/>
    <parent link="foot_left_3"/>
    <child link="foot_left_4"/>
    <axis xyz="0 0 1"/>
    <limit effort="6" velocity="6.6" lower="-1.5708" upper="1.5708"/>
  </joint>
  <!-- Joint from foot_left_2 to foot_left_3 -->
  <joint name="left_knee" type="revolute">
    <origin xyz="-6.41848e-16 -0.134 2.77556e-17" rpy="-1.26218e-29 -3.51852e-31 -6.52256e-15"/>
    <parent link="foot_left_2"/>
    <child link="foot_left_3"/>
    <axis xyz="0 0 1"/>
    <limit effort="6" velocity="6.6" lower="-0.785398" upper="0.785398"/>
  </joint>
  <!-- Joint from foot_left_1 to foot_left_2 -->
  <joint name="left_hip_pitch" type="revolute">
    <origin xyz="0.0235 -2.77556e-17 -0.02558" rpy="-1.11022e-16 1.5708 0"/>
    <parent link="foot_left_1"/>
    <child link="foot_left_2"/>
    <axis xyz="0 0 1"/>
    <limit effort="6" velocity="6.6" lower="-1.1781" upper="1.9635"/>
  </joint>
  <!-- Joint from stainless_steel_2mm_upper_leg_bracket_mir to foot_left_1 -->
  <joint name="left_hip_roll" type="revolute">
    <origin xyz="-0.0335 3.56659e-14 0.032" rpy="-1.5708 -1.30562e-13 1.5708"/>
    <parent link="stainless_steel_2mm_upper_leg_bracket_mir"/>
    <child link="foot_left_1"/>
    <axis xyz="0 0 1"/>
    <limit effort="6" velocity="6.6" lower="-1.5708" upper="0.785398"/>
  </joint>
  <!-- Joint from torso_kidsize25 to stainless_steel_2mm_upper_leg_bracket_mir -->
  <joint name="left_hip_yaw" type="revolute">
    <origin xyz="0.19561 0.0108657 0.272566" rpy="3.14159 1.14304e-14 -1.5708"/>
    <parent link="torso_kidsize25"/>
    <child link="stainless_steel_2mm_upper_leg_bracket_mir"/>
    <axis xyz="0 0 1"/>
    <limit effort="6" velocity="6.6" lower="-0.785398" upper="1.5708"/>
  </joint>
</robot>
